Workbook

Sheet Schedule
A1: first day of class: | B1: 44221 | I1: Chapt. | J1: Title | M1: Week | N1: & | O1: Month | P1: & | Q1: Date | R1: & | S1: Day | T1: & | U1: Chapter | V1: & | W1: Topic | X1: \\ | Y1: =IF(C2<>"","\hline","") -> \hline
C2: =IF(Calculations!A2,Dates!D2,"") -> W01 | D2: =IF(Calculations!A2,1,"") -> 1 | E2: =IF(Calculations!A2,Dates!I2,"") -> 1 | F2: =IF(Calculations!A2,Dates!J2,"") -> Jan | G2: =IF(Calculations!A2,Dates!K2,"") -> 25 | H2: =IF(Calculations!A2,Dates!H2,"") -> Mo | I2: 16 | J2: Temperature and Heat | K2: =IF(ISNUMBER(I2),1,0) -> 1 | M2: =Calculations!I2 -> \multirow{3}{*}{W01} | N2: =IF(Calculations!A2,Settings!$B$5,"") -> & | O2: =Calculations!J2 -> \multirow{3}{*}{Jan} | P2: =IF(Calculations!A2,Settings!$B$5,"") -> & | Q2: =Calculations!K2 -> 25 | R2: =IF(Calculations!A2,Settings!$B$5,"") -> & | S2: =Calculations!L2 -> Mo\rule{0pt}{11pt} | T2: =IF(Calculations!A2,Settings!$B$5,"") -> & | U2: =Calculations!M2 -> 16 | V2: =IF(Calculations!A2,Settings!$B$5,"") -> & | W2: =Calculations!N2 -> Temperature and Heat | X2: =Calculations!O2 -> \\* | Y2: =IF(Calculations!P2="","",Calculations!P2)
C3: =IF(Calculations!A3,Dates!D3,"") | D3: =IF(Calculations!A3,1,"") -> 1 | E3: =IF(Calculations!A3,Dates!I3,"") -> 1 | F3: =IF(Calculations!A3,Dates!J3,"") -> Jan | G3: =IF(Calculations!A3,Dates!K3,"") -> 27 | H3: =IF(Calculations!A3,Dates!H3,"") -> We | I3: 16 | J3: Temperature and Heat | K3: =IF(ISNUMBER(I3),1,0) -> 1 | M3: =Calculations!I3 | N3: =IF(Calculations!A3,Settings!$B$5,"") -> & | O3: =Calculations!J3 | P3: =IF(Calculations!A3,Settings!$B$5,"") -> & | Q3: =Calculations!K3 -> 27 | R3: =IF(Calculations!A3,Settings!$B$5,"") -> & | S3: =Calculations!L3 -> We | T3: =IF(Calculations!A3,Settings!$B$5,"") -> & | U3: =Calculations!M3 -> 16 | V3: =IF(Calculations!A3,Settings!$B$5,"") -> & | W3: =Calculations!N3 -> Temperature and Heat | X3: =Calculations!O3 -> \\* | Y3: =IF(Calculations!P3="","",Calculations!P3)
C4: =IF(Calculations!A4,Dates!D4,"") | D4: =IF(Calculations!A4,1,"") -> 1 | E4: =IF(Calculations!A4,Dates!I4,"") -> 1 | F4: =IF(Calculations!A4,Dates!J4,"") -> Jan | G4: =IF(Calculations!A4,Dates!K4,"") -> 29 | H4: =IF(Calculations!A4,Dates!H4,"") -> Fr | I4: 17 | J4: The Thermal Behavior of Matter | K4: =IF(ISNUMBER(I4),1,0) -> 1 | M4: =Calculations!I4 | N4: =IF(Calculations!A4,Settings!$B$5,"") -> & | O4: =Calculations!J4 | P4: =IF(Calculations!A4,Settings!$B$5,"") -> & | Q4: =Calculations!K4 -> 29 | R4: =IF(Calculations!A4,Settings!$B$5,"") -> & | S4: =Calculations!L4 -> Fr | T4: =IF(Calculations!A4,Settings!$B$5,"") -> & | U4: =Calculations!M4 -> 17 | V4: =IF(Calculations!A4,Settings!$B$5,"") -> & | W4: =Calculations!N4 -> The Thermal Behavior of Matter | X4: =Calculations!O4 -> \\ | Y4: =IF(Calculations!P4="","",Calculations!P4) -> \hline
A5: class meet days: | C5: =IF(Calculations!A5,Dates!D5,"") -> W02 | D5: =IF(Calculations!A5,1,"") -> 1 | E5: =IF(Calculations!A5,Dates!I5,"") -> 2 | F5: =IF(Calculations!A5,Dates!J5,"") -> Feb | G5: =IF(Calculations!A5,Dates!K5,"") -> 1 | H5: =IF(Calculations!A5,Dates!H5,"") -> Mo | I5: 17 | J5: The Thermal Behavior of Matter | K5: =IF(ISNUMBER(I5),1,0) -> 1 | M5: =Calculations!I5 -> \multirow{3}{*}{W02} | N5: =IF(Calculations!A5,Settings!$B$5,"") -> & | O5: =Calculations!J5 -> \multirow{3}{*}{Feb} | P5: =IF(Calculations!A5,Settings!$B$5,"") -> & | Q5: =Calculations!K5 -> 01 | R5: =IF(Calculations!A5,Settings!$B$5,"") -> & | S5: =Calculations!L5 -> Mo\rule{0pt}{11pt} | T5: =IF(Calculations!A5,Settings!$B$5,"") -> & | U5: =Calculations!M5 -> 17 | V5: =IF(Calculations!A5,Settings!$B$5,"") -> & | W5: =Calculations!N5 -> The Thermal Behavior of Matter | X5: =Calculations!O5 -> \\* | Y5: =IF(Calculations!P5="","",Calculations!P5)
A6: Mo | B6: x | C6: =IF(Calculations!A6,Dates!D6,"") | D6: =IF(Calculations!A6,1,"") -> 1 | E6: =IF(Calculations!A6,Dates!I6,"") -> 2 | F6: =IF(Calculations!A6,Dates!J6,"") -> Feb | G6: =IF(Calculations!A6,Dates!K6,"") -> 3 | H6: =IF(Calculations!A6,Dates!H6,"") -> We | I6: 18 | J6: Heat, Work, and the First Law of Thermodynamics | K6: =IF(ISNUMBER(I6),1,0) -> 1 | M6: =Calculations!I6 | N6: =IF(Calculations!A6,Settings!$B$5,"") -> & | O6: =Calculations!J6 | P6: =IF(Calculations!A6,Settings!$B$5,"") -> & | Q6: =Calculations!K6 -> 03 | R6: =IF(Calculations!A6,Settings!$B$5,"") -> & | S6: =Calculations!L6 -> We | T6: =IF(Calculations!A6,Settings!$B$5,"") -> & | U6: =Calculations!M6 -> 18 | V6: =IF(Calculations!A6,Settings!$B$5,"") -> & | W6: =Calculations!N6 -> Heat, Work, and the First Law of Thermodynamics | X6: =Calculations!O6 -> \\* | Y6: =IF(Calculations!P6="","",Calculations!P6)
A7: Tu | C7: =IF(Calculations!A7,Dates!D7,"") | D7: =IF(Calculations!A7,1,"") -> 1 | E7: =IF(Calculations!A7,Dates!I7,"") -> 2 | F7: =IF(Calculations!A7,Dates!J7,"") -> Feb | G7: =IF(Calculations!A7,Dates!K7,"") -> 5 | H7: =IF(Calculations!A7,Dates!H7,"") -> Fr | I7: 18 | J7: Heat, Work, and the First Law of Thermodynamics | K7: =IF(ISNUMBER(I7),1,0) -> 1 | M7: =Calculations!I7 | N7: =IF(Calculations!A7,Settings!$B$5,"") -> & | O7: =Calculations!J7 | P7: =IF(Calculations!A7,Settings!$B$5,"") -> & | Q7: =Calculations!K7 -> 05 | R7: =IF(Calculations!A7,Settings!$B$5,"") -> & | S7: =Calculations!L7 -> Fr | T7: =IF(Calculations!A7,Settings!$B$5,"") -> & | U7: =Calculations!M7 -> 18 | V7: =IF(Calculations!A7,Settings!$B$5,"") -> & | W7: =Calculations!N7 -> Heat, Work, and the First Law of Thermodynamics | X7: =Calculations!O7 -> \\ | Y7: =IF(Calculations!P7="","",Calculations!P7) -> \hline
A8: We | B8: x | C8: =IF(Calculations!A8,Dates!D8,"") -> W03 | D8: =IF(Calculations!A8,1,"") -> 1 | E8: =IF(Calculations!A8,Dates!I8,"") -> 2 | F8: =IF(Calculations!A8,Dates!J8,"") -> Feb | G8: =IF(Calculations!A8,Dates!K8,"") -> 8 | H8: =IF(Calculations!A8,Dates!H8,"") -> Mo | I8: 19 | J8: Spring Vacation | K8: =IF(ISNUMBER(I8),1,0) -> 1 | M8: =Calculations!I8 -> \multirow{3}{*}{W03} | N8: =IF(Calculations!A8,Settings!$B$5,"") -> & | O8: =Calculations!J8 -> \multirow{3}{*}{Feb} | P8: =IF(Calculations!A8,Settings!$B$5,"") -> & | Q8: =Calculations!K8 -> 08 | R8: =IF(Calculations!A8,Settings!$B$5,"") -> & | S8: =Calculations!L8 -> Mo\rule{0pt}{11pt} | T8: =IF(Calculations!A8,Settings!$B$5,"") -> & | U8: =Calculations!M8 -> 19 | V8: =IF(Calculations!A8,Settings!$B$5,"") -> & | W8: =Calculations!N8 -> Spring Vacation | X8: =Calculations!O8 -> \\* | Y8: =IF(Calculations!P8="","",Calculations!P8)
A9: Th | C9: =IF(Calculations!A9,Dates!D9,"") | D9: =IF(Calculations!A9,1,"") -> 1 | E9: =IF(Calculations!A9,Dates!I9,"") -> 2 | F9: =IF(Calculations!A9,Dates!J9,"") -> Feb | G9: =IF(Calculations!A9,Dates!K9,"") -> 10 | H9: =IF(Calculations!A9,Dates!H9,"") -> We | I9: 19 | J9: The Second Law of Thermodynamics | K9: =IF(ISNUMBER(I9),1,0) -> 1 | M9: =Calculations!I9 | N9: =IF(Calculations!A9,Settings!$B$5,"") -> & | O9: =Calculations!J9 | P9: =IF(Calculations!A9,Settings!$B$5,"") -> & | Q9: =Calculations!K9 -> 10 | R9: =IF(Calculations!A9,Settings!$B$5,"") -> & | S9: =Calculations!L9 -> We | T9: =IF(Calculations!A9,Settings!$B$5,"") -> & | U9: =Calculations!M9 -> 19 | V9: =IF(Calculations!A9,Settings!$B$5,"") -> & | W9: =Calculations!N9 -> The Second Law of Thermodynamics | X9: =Calculations!O9 -> \\* | Y9: =IF(Calculations!P9="","",Calculations!P9)
A10: Fr | B10: x | C10: =IF(Calculations!A10,Dates!D10,"") | D10: =IF(Calculations!A10,1,"") -> 1 | E10: =IF(Calculations!A10,Dates!I10,"") -> 2 | F10: =IF(Calculations!A10,Dates!J10,"") -> Feb | G10: =IF(Calculations!A10,Dates!K10,"") -> 12 | H10: =IF(Calculations!A10,Dates!H10,"") -> Fr | I10: 19 | J10: The Second Law of Thermodynamics | K10: =IF(ISNUMBER(I10),1,0) -> 1 | M10: =Calculations!I10 | N10: =IF(Calculations!A10,Settings!$B$5,"") -> & | O10: =Calculations!J10 | P10: =IF(Calculations!A10,Settings!$B$5,"") -> & | Q10: =Calculations!K10 -> 12 | R10: =IF(Calculations!A10,Settings!$B$5,"") -> & | S10: =Calculations!L10 -> Fr | T10: =IF(Calculations!A10,Settings!$B$5,"") -> & | U10: =Calculations!M10 -> 19 | V10: =IF(Calculations!A10,Settings!$B$5,"") -> & | W10: =Calculations!N10 -> The Second Law of Thermodynamics | X10: =Calculations!O10 -> \\ | Y10: =IF(Calculations!P10="","",Calculations!P10) -> \hline
C11: =IF(Calculations!A11,Dates!D11,"") -> W04 | D11: =IF(Calculations!A11,1,"") -> 1 | E11: =IF(Calculations!A11,Dates!I11,"") -> 2 | F11: =IF(Calculations!A11,Dates!J11,"") -> Feb | G11: =IF(Calculations!A11,Dates!K11,"") -> 15 | H11: =IF(Calculations!A11,Dates!H11,"") -> Mo | I11: No class | J11: President's Day | K11: =IF(ISNUMBER(I11),1,0) -> 0 | M11: =Calculations!I11 -> \multirow{3}{*}{W04} | N11: =IF(Calculations!A11,Settings!$B$5,"") -> & | O11: =Calculations!J11 -> \multirow{3}{*}{Feb} | P11: =IF(Calculations!A11,Settings!$B$5,"") -> & | Q11: =Calculations!K11 -> 15 | R11: =IF(Calculations!A11,Settings!$B$5,"") -> & | S11: =Calculations!L11 -> Mo\rule{0pt}{11pt} | T11: =IF(Calculations!A11,Settings!$B$5,"") -> & | U11: =Calculations!M11 -> No class | V11: =IF(Calculations!A11,Settings!$B$5,"") -> & | W11: =Calculations!N11 -> President's Day | X11: =Calculations!O11 -> \\* | Y11: =IF(Calculations!P11="","",Calculations!P11)
A12: Resulting | C12: =IF(Calculations!A12,Dates!D12,"") | D12: =IF(Calculations!A12,1,"") -> 1 | E12: =IF(Calculations!A12,Dates!I12,"") -> 2 | F12: =IF(Calculations!A12,Dates!J12,"") -> Feb | G12: =IF(Calculations!A12,Dates!K12,"") -> 17 | H12: =IF(Calculations!A12,Dates!H12,"") -> We | I12: 20 | J12: Electric Charge, Force, and Field | K12: =IF(ISNUMBER(I12),1,0) -> 1 | M12: =Calculations!I12 | N12: =IF(Calculations!A12,Settings!$B$5,"") -> & | O12: =Calculations!J12 | P12: =IF(Calculations!A12,Settings!$B$5,"") -> & | Q12: =Calculations!K12 -> 17 | R12: =IF(Calculations!A12,Settings!$B$5,"") -> & | S12: =Calculations!L12 -> We | T12: =IF(Calculations!A12,Settings!$B$5,"") -> & | U12: =Calculations!M12 -> 20 | V12: =IF(Calculations!A12,Settings!$B$5,"") -> & | W12: =Calculations!N12 -> Electric Charge, Force, and Field | X12: =Calculations!O12 -> \\* | Y12: =IF(Calculations!P12="","",Calculations!P12)
A13: LaTeX → | B13: =_xlfn.TEXTJOIN(CHAR(10),1,Export!B5:B264) -> \multirow{3}{*}{W01} & \multirow{3}{*}{Jan} & 25 & Mo\rule{0pt}{11pt} & 16 & Temperature and Heat \\* & & 27 & We & 16 & Temperature and Heat \\* & & 29 & Fr & 17 & The Thermal Behavior of Matter \\ \hline \multirow{3}{*}{W02} & \multirow{3}{*}{Feb} & 01 & Mo\rule{0pt}{11pt} & 17 & The Thermal Behavior of Matter \\* & & 03 & We & 18 & Heat, Work, and the First Law of Thermodynamics \\* & & 05 & Fr & 18 & Heat, Work, and the First Law of Thermodynamics \\ \hline \multirow{3}{*}{W03} & \multirow{3}{*}{Feb} & 08 & Mo\rule{0pt}{11pt} & 19 & Spring Vacation \\* & & 10 & We & 19 & The Second Law of Thermodynamics \\* & & 12 & Fr & 19 & The Second Law of Thermodynamics \\ \hline \multirow{3}{*}{W04} & \multirow{3}{*}{Feb} & 15 & Mo\rule{0pt}{11pt} & No class & President's Day \\* & & 17 & We & 20 & Electric Charge, Force, and Field \\* & & 19 & Fr & 20 & Electric Charge, Force, and Field \\ \hline \multirow{3}{*}{W05} & \multirow{3}{*}{Feb} & 22 & Mo\rule{0pt}{11pt} & 21 & Gauss’s Law \\* & & 24 & We & 21 & Gauss’s Law \\* & & 26 & Fr & \textbf{Midterm 1} & \\ \hline \multirow{3}{*}{W06} & \multirow{3}{*}{Mar} & 01 & Mo\rule{0pt}{11pt} & 21 & Gauss’s Law \\* & & 03 & We & 22 & Electric Potential \\* & & 05 & Fr & 22 & Electric Potential \\ \hline \multirow{3}{*}{W07} & \multirow{3}{*}{Mar} & 08 & Mo\rule{0pt}{11pt} & 23 & Electrostatic Energy and Capacitors \\* & & 10 & We & 23 & Electrostatic Energy and Capacitors \\* & & 12 & Fr & 24 & Electric Current \\ \hline \multirow{3}{*}{W08} & \multirow{3}{*}{Mar} & 15 & Mo\rule{0pt}{11pt} & No class & Spring Vacation \\* & & 17 & We & No class & Spring Vacation \\* & & 19 & Fr & No class & Spring Vacation \\ \hline \multirow{3}{*}{W09} & \multirow{3}{*}{Mar} & 22 & Mo\rule{0pt}{11pt} & 24 & Electric Current \\* & & 24 & We & 25 & Electric Circuits \\* & & 26 & Fr & 25 & Electric Circuits \\ \hline \multirow{3}{*}{W10} & \multirow{2}{*}{Mar} & 29 & Mo\rule{0pt}{11pt} & 26 & Magnetism: Force and Field \\* & & 31 & We & 26 & Magnetism: Force and Field \\* & Apr & 02 & Fr & 26 & Magnetism: Force and Field \\ \hline \multirow{3}{*}{W11} & \multirow{3}{*}{Apr} & 05 & Mo\rule{0pt}{11pt} & 26 & Magnetism: Force and Field \\* & & 07 & We & 27 & Electromagnetic Induction \\* & & 09 & Fr & \textbf{Midterm 2} & \\ \hline \multirow{3}{*}{W12} & \multirow{3}{*}{Apr} & 12 & Mo\rule{0pt}{11pt} & 27 & Electromagnetic Induction \\* & & 14 & We & 27 & Electromagnetic Induction \\* & & 16 & Fr & 28 & Alternating-Current Circuits \\ \hline \multirow{3}{*}{W13} & \multirow{3}{*}{Apr} & 19 & Mo\rule{0pt}{11pt} & No class & Patriot’s Day \\* & & 21 & We & 28 & Alternating-Current Circuits \\* & & 23 & Fr & 29 & Maxwell’s Equations and Electromagnetic Waves \\ \hline \multirow{3}{*}{W14} & \multirow{3}{*}{Apr} & 26 & Mo\rule{0pt}{11pt} & 29 & Maxwell’s Equations and Electromagnetic Waves \\* & & 28 & We & 30 & Reflection and Refraction \\* & & 30 & Fr & 30 & Reflection and Refraction \\ \hline \multirow{3}{*}{W15} & \multirow{3}{*}{May} & 03 & Mo\rule{0pt}{11pt} & 31 & Images and Optical Instruments \\* & & 05 & We & 31 & Images and Optical Instruments \\* & & 07 & Fr & 32 & Interference and Diffraction \\ \hline \multirow{2}{*}{W16} & \multirow{2}{*}{May} & 10 & Mo\rule{0pt}{11pt} & 32 & Interference and Diffraction \\* & & 12 & We & 32 & Interference and Diffraction \\ \hline | C13: =IF(Calculations!A13,Dates!D13,"") | D13: =IF(Calculations!A13,1,"") -> 1 | E13: =IF(Calculations!A13,Dates!I13,"") -> 2 | F13: =IF(Calculations!A13,Dates!J13,"") -> Feb | G13: =IF(Calculations!A13,Dates!K13,"") -> 19 | H13: =IF(Calculations!A13,Dates!H13,"") -> Fr | I13: 20 | J13: Electric Charge, Force, and Field | K13: =IF(ISNUMBER(I13),1,0) -> 1 | M13: =Calculations!I13 | N13: =IF(Calculations!A13,Settings!$B$5,"") -> & | O13: =Calculations!J13 | P13: =IF(Calculations!A13,Settings!$B$5,"") -> & | Q13: =Calculations!K13 -> 19 | R13: =IF(Calculations!A13,Settings!$B$5,"") -> & | S13: =Calculations!L13 -> Fr | T13: =IF(Calculations!A13,Settings!$B$5,"") -> & | U13: =Calculations!M13 -> 20 | V13: =IF(Calculations!A13,Settings!$B$5,"") -> & | W13: =Calculations!N13 -> Electric Charge, Force, and Field | X13: =Calculations!O13 -> \\ | Y13: =IF(Calculations!P13="","",Calculations!P13) -> \hline
A14: code | C14: =IF(Calculations!A14,Dates!D14,"") -> W05 | D14: =IF(Calculations!A14,1,"") -> 1 | E14: =IF(Calculations!A14,Dates!I14,"") -> 2 | F14: =IF(Calculations!A14,Dates!J14,"") -> Feb | G14: =IF(Calculations!A14,Dates!K14,"") -> 22 | H14: =IF(Calculations!A14,Dates!H14,"") -> Mo | I14: 21 | J14: Gauss’s Law | K14: =IF(ISNUMBER(I14),1,0) -> 1 | M14: =Calculations!I14 -> \multirow{3}{*}{W05} | N14: =IF(Calculations!A14,Settings!$B$5,"") -> & | O14: =Calculations!J14 -> \multirow{3}{*}{Feb} | P14: =IF(Calculations!A14,Settings!$B$5,"") -> & | Q14: =Calculations!K14 -> 22 | R14: =IF(Calculations!A14,Settings!$B$5,"") -> & | S14: =Calculations!L14 -> Mo\rule{0pt}{11pt} | T14: =IF(Calculations!A14,Settings!$B$5,"") -> & | U14: =Calculations!M14 -> 21 | V14: =IF(Calculations!A14,Settings!$B$5,"") -> & | W14: =Calculations!N14 -> Gauss’s Law | X14: =Calculations!O14 -> \\* | Y14: =IF(Calculations!P14="","",Calculations!P14)
C15: =IF(Calculations!A15,Dates!D15,"") | D15: =IF(Calculations!A15,1,"") -> 1 | E15: =IF(Calculations!A15,Dates!I15,"") -> 2 | F15: =IF(Calculations!A15,Dates!J15,"") -> Feb | G15: =IF(Calculations!A15,Dates!K15,"") -> 24 | H15: =IF(Calculations!A15,Dates!H15,"") -> We | I15: 21 | J15: Gauss’s Law | K15: =IF(ISNUMBER(I15),1,0) -> 1 | M15: =Calculations!I15 | N15: =IF(Calculations!A15,Settings!$B$5,"") -> & | O15: =Calculations!J15 | P15: =IF(Calculations!A15,Settings!$B$5,"") -> & | Q15: =Calculations!K15 -> 24 | R15: =IF(Calculations!A15,Settings!$B$5,"") -> & | S15: =Calculations!L15 -> We | T15: =IF(Calculations!A15,Settings!$B$5,"") -> & | U15: =Calculations!M15 -> 21 | V15: =IF(Calculations!A15,Settings!$B$5,"") -> & | W15: =Calculations!N15 -> Gauss’s Law | X15: =Calculations!O15 -> \\* | Y15: =IF(Calculations!P15="","",Calculations!P15)
A16: number of | C16: =IF(Calculations!A16,Dates!D16,"") | D16: =IF(Calculations!A16,1,"") -> 1 | E16: =IF(Calculations!A16,Dates!I16,"") -> 2 | F16: =IF(Calculations!A16,Dates!J16,"") -> Feb | G16: =IF(Calculations!A16,Dates!K16,"") -> 26 | H16: =IF(Calculations!A16,Dates!H16,"") -> Fr | I16: \textbf{Midterm 1} | K16: =IF(ISNUMBER(I16),1,0) -> 0 | M16: =Calculations!I16 | N16: =IF(Calculations!A16,Settings!$B$5,"") -> & | O16: =Calculations!J16 | P16: =IF(Calculations!A16,Settings!$B$5,"") -> & | Q16: =Calculations!K16 -> 26 | R16: =IF(Calculations!A16,Settings!$B$5,"") -> & | S16: =Calculations!L16 -> Fr | T16: =IF(Calculations!A16,Settings!$B$5,"") -> & | U16: =Calculations!M16 -> \textbf{Midterm 1} | V16: =IF(Calculations!A16,Settings!$B$5,"") -> & | W16: =Calculations!N16 | X16: =Calculations!O16 -> \\ | Y16: =IF(Calculations!P16="","",Calculations!P16) -> \hline
A17: actual → | B17: =COUNT(I2:I261) -> 40 | C17: =IF(Calculations!A17,Dates!D17,"") -> W06 | D17: =IF(Calculations!A17,1,"") -> 1 | E17: =IF(Calculations!A17,Dates!I17,"") -> 3 | F17: =IF(Calculations!A17,Dates!J17,"") -> Mar | G17: =IF(Calculations!A17,Dates!K17,"") -> 1 | H17: =IF(Calculations!A17,Dates!H17,"") -> Mo | I17: 21 | J17: Gauss’s Law | K17: =IF(ISNUMBER(I17),1,0) -> 1 | M17: =Calculations!I17 -> \multirow{3}{*}{W06} | N17: =IF(Calculations!A17,Settings!$B$5,"") -> & | O17: =Calculations!J17 -> \multirow{3}{*}{Mar} | P17: =IF(Calculations!A17,Settings!$B$5,"") -> & | Q17: =Calculations!K17 -> 01 | R17: =IF(Calculations!A17,Settings!$B$5,"") -> & | S17: =Calculations!L17 -> Mo\rule{0pt}{11pt} | T17: =IF(Calculations!A17,Settings!$B$5,"") -> & | U17: =Calculations!M17 -> 21 | V17: =IF(Calculations!A17,Settings!$B$5,"") -> & | W17: =Calculations!N17 -> Gauss’s Law | X17: =Calculations!O17 -> \\* | Y17: =IF(Calculations!P17="","",Calculations!P17)
A18: lecture days | C18: =IF(Calculations!A18,Dates!D18,"") | D18: =IF(Calculations!A18,1,"") -> 1 | E18: =IF(Calculations!A18,Dates!I18,"") -> 3 | F18: =IF(Calculations!A18,Dates!J18,"") -> Mar | G18: =IF(Calculations!A18,Dates!K18,"") -> 3 | H18: =IF(Calculations!A18,Dates!H18,"") -> We | I18: 22 | J18: Electric Potential | K18: =IF(ISNUMBER(I18),1,0) -> 1 | M18: =Calculations!I18 | N18: =IF(Calculations!A18,Settings!$B$5,"") -> & | O18: =Calculations!J18 | P18: =IF(Calculations!A18,Settings!$B$5,"") -> & | Q18: =Calculations!K18 -> 03 | R18: =IF(Calculations!A18,Settings!$B$5,"") -> & | S18: =Calculations!L18 -> We | T18: =IF(Calculations!A18,Settings!$B$5,"") -> & | U18: =Calculations!M18 -> 22 | V18: =IF(Calculations!A18,Settings!$B$5,"") -> & | W18: =Calculations!N18 -> Electric Potential | X18: =Calculations!O18 -> \\* | Y18: =IF(Calculations!P18="","",Calculations!P18)
C19: =IF(Calculations!A19,Dates!D19,"") | D19: =IF(Calculations!A19,1,"") -> 1 | E19: =IF(Calculations!A19,Dates!I19,"") -> 3 | F19: =IF(Calculations!A19,Dates!J19,"") -> Mar | G19: =IF(Calculations!A19,Dates!K19,"") -> 5 | H19: =IF(Calculations!A19,Dates!H19,"") -> Fr | I19: 22 | J19: Electric Potential | K19: =IF(ISNUMBER(I19),1,0) -> 1 | M19: =Calculations!I19 | N19: =IF(Calculations!A19,Settings!$B$5,"") -> & | O19: =Calculations!J19 | P19: =IF(Calculations!A19,Settings!$B$5,"") -> & | Q19: =Calculations!K19 -> 05 | R19: =IF(Calculations!A19,Settings!$B$5,"") -> & | S19: =Calculations!L19 -> Fr | T19: =IF(Calculations!A19,Settings!$B$5,"") -> & | U19: =Calculations!M19 -> 22 | V19: =IF(Calculations!A19,Settings!$B$5,"") -> & | W19: =Calculations!N19 -> Electric Potential | X19: =Calculations!O19 -> \\ | Y19: =IF(Calculations!P19="","",Calculations!P19) -> \hline
A20: Area that can be used for other | C20: =IF(Calculations!A20,Dates!D20,"") -> W07 | D20: =IF(Calculations!A20,1,"") -> 1 | E20: =IF(Calculations!A20,Dates!I20,"") -> 3 | F20: =IF(Calculations!A20,Dates!J20,"") -> Mar | G20: =IF(Calculations!A20,Dates!K20,"") -> 8 | H20: =IF(Calculations!A20,Dates!H20,"") -> Mo | I20: 23 | J20: Electrostatic Energy and Capacitors | K20: =IF(ISNUMBER(I20),1,0) -> 1 | M20: =Calculations!I20 -> \multirow{3}{*}{W07} | N20: =IF(Calculations!A20,Settings!$B$5,"") -> & | O20: =Calculations!J20 -> \multirow{3}{*}{Mar} | P20: =IF(Calculations!A20,Settings!$B$5,"") -> & | Q20: =Calculations!K20 -> 08 | R20: =IF(Calculations!A20,Settings!$B$5,"") -> & | S20: =Calculations!L20 -> Mo\rule{0pt}{11pt} | T20: =IF(Calculations!A20,Settings!$B$5,"") -> & | U20: =Calculations!M20 -> 23 | V20: =IF(Calculations!A20,Settings!$B$5,"") -> & | W20: =Calculations!N20 -> Electrostatic Energy and Capacitors | X20: =Calculations!O20 -> \\* | Y20: =IF(Calculations!P20="","",Calculations!P20)
A21: miscellaneous calculations: | C21: =IF(Calculations!A21,Dates!D21,"") | D21: =IF(Calculations!A21,1,"") -> 1 | E21: =IF(Calculations!A21,Dates!I21,"") -> 3 | F21: =IF(Calculations!A21,Dates!J21,"") -> Mar | G21: =IF(Calculations!A21,Dates!K21,"") -> 10 | H21: =IF(Calculations!A21,Dates!H21,"") -> We | I21: 23 | J21: Electrostatic Energy and Capacitors | K21: =IF(ISNUMBER(I21),1,0) -> 1 | M21: =Calculations!I21 | N21: =IF(Calculations!A21,Settings!$B$5,"") -> & | O21: =Calculations!J21 | P21: =IF(Calculations!A21,Settings!$B$5,"") -> & | Q21: =Calculations!K21 -> 10 | R21: =IF(Calculations!A21,Settings!$B$5,"") -> & | S21: =Calculations!L21 -> We | T21: =IF(Calculations!A21,Settings!$B$5,"") -> & | U21: =Calculations!M21 -> 23 | V21: =IF(Calculations!A21,Settings!$B$5,"") -> & | W21: =Calculations!N21 -> Electrostatic Energy and Capacitors | X21: =Calculations!O21 -> \\* | Y21: =IF(Calculations!P21="","",Calculations!P21)
A22: ⇓ | B22: ⇓ | C22: =IF(Calculations!A22,Dates!D22,"") | D22: =IF(Calculations!A22,1,"") -> 1 | E22: =IF(Calculations!A22,Dates!I22,"") -> 3 | F22: =IF(Calculations!A22,Dates!J22,"") -> Mar | G22: =IF(Calculations!A22,Dates!K22,"") -> 12 | H22: =IF(Calculations!A22,Dates!H22,"") -> Fr | I22: 24 | J22: Electric Current | K22: =IF(ISNUMBER(I22),1,0) -> 1 | M22: =Calculations!I22 | N22: =IF(Calculations!A22,Settings!$B$5,"") -> & | O22: =Calculations!J22 | P22: =IF(Calculations!A22,Settings!$B$5,"") -> & | Q22: =Calculations!K22 -> 12 | R22: =IF(Calculations!A22,Settings!$B$5,"") -> & | S22: =Calculations!L22 -> Fr | T22: =IF(Calculations!A22,Settings!$B$5,"") -> & | U22: =Calculations!M22 -> 24 | V22: =IF(Calculations!A22,Settings!$B$5,"") -> & | W22: =Calculations!N22 -> Electric Current | X22: =Calculations!O22 -> \\ | Y22: =IF(Calculations!P22="","",Calculations!P22) -> \hline
C23: =IF(Calculations!A23,Dates!D23,"") -> W08 | D23: =IF(Calculations!A23,1,"") -> 1 | E23: =IF(Calculations!A23,Dates!I23,"") -> 3 | F23: =IF(Calculations!A23,Dates!J23,"") -> Mar | G23: =IF(Calculations!A23,Dates!K23,"") -> 15 | H23: =IF(Calculations!A23,Dates!H23,"") -> Mo | I23: No class | J23: Spring Vacation | K23: =IF(ISNUMBER(I23),1,0) -> 0 | M23: =Calculations!I23 -> \multirow{3}{*}{W08} | N23: =IF(Calculations!A23,Settings!$B$5,"") -> & | O23: =Calculations!J23 -> \multirow{3}{*}{Mar} | P23: =IF(Calculations!A23,Settings!$B$5,"") -> & | Q23: =Calculations!K23 -> 15 | R23: =IF(Calculations!A23,Settings!$B$5,"") -> & | S23: =Calculations!L23 -> Mo\rule{0pt}{11pt} | T23: =IF(Calculations!A23,Settings!$B$5,"") -> & | U23: =Calculations!M23 -> No class | V23: =IF(Calculations!A23,Settings!$B$5,"") -> & | W23: =Calculations!N23 -> Spring Vacation | X23: =Calculations!O23 -> \\* | Y23: =IF(Calculations!P23="","",Calculations!P23)
C24: =IF(Calculations!A24,Dates!D24,"") | D24: =IF(Calculations!A24,1,"") -> 1 | E24: =IF(Calculations!A24,Dates!I24,"") -> 3 | F24: =IF(Calculations!A24,Dates!J24,"") -> Mar | G24: =IF(Calculations!A24,Dates!K24,"") -> 17 | H24: =IF(Calculations!A24,Dates!H24,"") -> We | I24: No class | J24: Spring Vacation | K24: =IF(ISNUMBER(I24),1,0) -> 0 | M24: =Calculations!I24 | N24: =IF(Calculations!A24,Settings!$B$5,"") -> & | O24: =Calculations!J24 | P24: =IF(Calculations!A24,Settings!$B$5,"") -> & | Q24: =Calculations!K24 -> 17 | R24: =IF(Calculations!A24,Settings!$B$5,"") -> & | S24: =Calculations!L24 -> We | T24: =IF(Calculations!A24,Settings!$B$5,"") -> & | U24: =Calculations!M24 -> No class | V24: =IF(Calculations!A24,Settings!$B$5,"") -> & | W24: =Calculations!N24 -> Spring Vacation | X24: =Calculations!O24 -> \\* | Y24: =IF(Calculations!P24="","",Calculations!P24)
C25: =IF(Calculations!A25,Dates!D25,"") | D25: =IF(Calculations!A25,1,"") -> 1 | E25: =IF(Calculations!A25,Dates!I25,"") -> 3 | F25: =IF(Calculations!A25,Dates!J25,"") -> Mar | G25: =IF(Calculations!A25,Dates!K25,"") -> 19 | H25: =IF(Calculations!A25,Dates!H25,"") -> Fr | I25: No class | J25: Spring Vacation | K25: =IF(ISNUMBER(I25),1,0) -> 0 | M25: =Calculations!I25 | N25: =IF(Calculations!A25,Settings!$B$5,"") -> & | O25: =Calculations!J25 | P25: =IF(Calculations!A25,Settings!$B$5,"") -> & | Q25: =Calculations!K25 -> 19 | R25: =IF(Calculations!A25,Settings!$B$5,"") -> & | S25: =Calculations!L25 -> Fr | T25: =IF(Calculations!A25,Settings!$B$5,"") -> & | U25: =Calculations!M25 -> No class | V25: =IF(Calculations!A25,Settings!$B$5,"") -> & | W25: =Calculations!N25 -> Spring Vacation | X25: =Calculations!O25 -> \\ | Y25: =IF(Calculations!P25="","",Calculations!P25) -> \hline
C26: =IF(Calculations!A26,Dates!D26,"") -> W09 | D26: =IF(Calculations!A26,1,"") -> 1 | E26: =IF(Calculations!A26,Dates!I26,"") -> 3 | F26: =IF(Calculations!A26,Dates!J26,"") -> Mar | G26: =IF(Calculations!A26,Dates!K26,"") -> 22 | H26: =IF(Calculations!A26,Dates!H26,"") -> Mo | I26: 24 | J26: Electric Current | K26: =IF(ISNUMBER(I26),1,0) -> 1 | M26: =Calculations!I26 -> \multirow{3}{*}{W09} | N26: =IF(Calculations!A26,Settings!$B$5,"") -> & | O26: =Calculations!J26 -> \multirow{3}{*}{Mar} | P26: =IF(Calculations!A26,Settings!$B$5,"") -> & | Q26: =Calculations!K26 -> 22 | R26: =IF(Calculations!A26,Settings!$B$5,"") -> & | S26: =Calculations!L26 -> Mo\rule{0pt}{11pt} | T26: =IF(Calculations!A26,Settings!$B$5,"") -> & | U26: =Calculations!M26 -> 24 | V26: =IF(Calculations!A26,Settings!$B$5,"") -> & | W26: =Calculations!N26 -> Electric Current | X26: =Calculations!O26 -> \\* | Y26: =IF(Calculations!P26="","",Calculations!P26)
C27: =IF(Calculations!A27,Dates!D27,"") | D27: =IF(Calculations!A27,1,"") -> 1 | E27: =IF(Calculations!A27,Dates!I27,"") -> 3 | F27: =IF(Calculations!A27,Dates!J27,"") -> Mar | G27: =IF(Calculations!A27,Dates!K27,"") -> 24 | H27: =IF(Calculations!A27,Dates!H27,"") -> We | I27: 25 | J27: Electric Circuits | K27: =IF(ISNUMBER(I27),1,0) -> 1 | M27: =Calculations!I27 | N27: =IF(Calculations!A27,Settings!$B$5,"") -> & | O27: =Calculations!J27 | P27: =IF(Calculations!A27,Settings!$B$5,"") -> & | Q27: =Calculations!K27 -> 24 | R27: =IF(Calculations!A27,Settings!$B$5,"") -> & | S27: =Calculations!L27 -> We | T27: =IF(Calculations!A27,Settings!$B$5,"") -> & | U27: =Calculations!M27 -> 25 | V27: =IF(Calculations!A27,Settings!$B$5,"") -> & | W27: =Calculations!N27 -> Electric Circuits | X27: =Calculations!O27 -> \\* | Y27: =IF(Calculations!P27="","",Calculations!P27)
C28: =IF(Calculations!A28,Dates!D28,"") | D28: =IF(Calculations!A28,1,"") -> 1 | E28: =IF(Calculations!A28,Dates!I28,"") -> 3 | F28: =IF(Calculations!A28,Dates!J28,"") -> Mar | G28: =IF(Calculations!A28,Dates!K28,"") -> 26 | H28: =IF(Calculations!A28,Dates!H28,"") -> Fr | I28: 25 | J28: Electric Circuits | K28: =IF(ISNUMBER(I28),1,0) -> 1 | M28: =Calculations!I28 | N28: =IF(Calculations!A28,Settings!$B$5,"") -> & | O28: =Calculations!J28 | P28: =IF(Calculations!A28,Settings!$B$5,"") -> & | Q28: =Calculations!K28 -> 26 | R28: =IF(Calculations!A28,Settings!$B$5,"") -> & | S28: =Calculations!L28 -> Fr | T28: =IF(Calculations!A28,Settings!$B$5,"") -> & | U28: =Calculations!M28 -> 25 | V28: =IF(Calculations!A28,Settings!$B$5,"") -> & | W28: =Calculations!N28 -> Electric Circuits | X28: =Calculations!O28 -> \\ | Y28: =IF(Calculations!P28="","",Calculations!P28) -> \hline
C29: =IF(Calculations!A29,Dates!D29,"") -> W10 | D29: =IF(Calculations!A29,1,"") -> 1 | E29: =IF(Calculations!A29,Dates!I29,"") -> 3 | F29: =IF(Calculations!A29,Dates!J29,"") -> Mar | G29: =IF(Calculations!A29,Dates!K29,"") -> 29 | H29: =IF(Calculations!A29,Dates!H29,"") -> Mo | I29: 26 | J29: Magnetism: Force and Field | K29: =IF(ISNUMBER(I29),1,0) -> 1 | M29: =Calculations!I29 -> \multirow{3}{*}{W10} | N29: =IF(Calculations!A29,Settings!$B$5,"") -> & | O29: =Calculations!J29 -> \multirow{2}{*}{Mar} | P29: =IF(Calculations!A29,Settings!$B$5,"") -> & | Q29: =Calculations!K29 -> 29 | R29: =IF(Calculations!A29,Settings!$B$5,"") -> & | S29: =Calculations!L29 -> Mo\rule{0pt}{11pt} | T29: =IF(Calculations!A29,Settings!$B$5,"") -> & | U29: =Calculations!M29 -> 26 | V29: =IF(Calculations!A29,Settings!$B$5,"") -> & | W29: =Calculations!N29 -> Magnetism: Force and Field | X29: =Calculations!O29 -> \\* | Y29: =IF(Calculations!P29="","",Calculations!P29)
C30: =IF(Calculations!A30,Dates!D30,"") | D30: =IF(Calculations!A30,1,"") -> 1 | E30: =IF(Calculations!A30,Dates!I30,"") -> 3 | F30: =IF(Calculations!A30,Dates!J30,"") -> Mar | G30: =IF(Calculations!A30,Dates!K30,"") -> 31 | H30: =IF(Calculations!A30,Dates!H30,"") -> We | I30: 26 | J30: Magnetism: Force and Field | K30: =IF(ISNUMBER(I30),1,0) -> 1 | M30: =Calculations!I30 | N30: =IF(Calculations!A30,Settings!$B$5,"") -> & | O30: =Calculations!J30 | P30: =IF(Calculations!A30,Settings!$B$5,"") -> & | Q30: =Calculations!K30 -> 31 | R30: =IF(Calculations!A30,Settings!$B$5,"") -> & | S30: =Calculations!L30 -> We | T30: =IF(Calculations!A30,Settings!$B$5,"") -> & | U30: =Calculations!M30 -> 26 | V30: =IF(Calculations!A30,Settings!$B$5,"") -> & | W30: =Calculations!N30 -> Magnetism: Force and Field | X30: =Calculations!O30 -> \\* | Y30: =IF(Calculations!P30="","",Calculations!P30)
C31: =IF(Calculations!A31,Dates!D31,"") | D31: =IF(Calculations!A31,1,"") -> 1 | E31: =IF(Calculations!A31,Dates!I31,"") -> 4 | F31: =IF(Calculations!A31,Dates!J31,"") -> Apr | G31: =IF(Calculations!A31,Dates!K31,"") -> 2 | H31: =IF(Calculations!A31,Dates!H31,"") -> Fr | I31: 26 | J31: Magnetism: Force and Field | K31: =IF(ISNUMBER(I31),1,0) -> 1 | M31: =Calculations!I31 | N31: =IF(Calculations!A31,Settings!$B$5,"") -> & | O31: =Calculations!J31 -> Apr | P31: =IF(Calculations!A31,Settings!$B$5,"") -> & | Q31: =Calculations!K31 -> 02 | R31: =IF(Calculations!A31,Settings!$B$5,"") -> & | S31: =Calculations!L31 -> Fr | T31: =IF(Calculations!A31,Settings!$B$5,"") -> & | U31: =Calculations!M31 -> 26 | V31: =IF(Calculations!A31,Settings!$B$5,"") -> & | W31: =Calculations!N31 -> Magnetism: Force and Field | X31: =Calculations!O31 -> \\ | Y31: =IF(Calculations!P31="","",Calculations!P31) -> \hline
C32: =IF(Calculations!A32,Dates!D32,"") -> W11 | D32: =IF(Calculations!A32,1,"") -> 1 | E32: =IF(Calculations!A32,Dates!I32,"") -> 4 | F32: =IF(Calculations!A32,Dates!J32,"") -> Apr | G32: =IF(Calculations!A32,Dates!K32,"") -> 5 | H32: =IF(Calculations!A32,Dates!H32,"") -> Mo | I32: 26 | J32: Magnetism: Force and Field | K32: =IF(ISNUMBER(I32),1,0) -> 1 | M32: =Calculations!I32 -> \multirow{3}{*}{W11} | N32: =IF(Calculations!A32,Settings!$B$5,"") -> & | O32: =Calculations!J32 -> \multirow{3}{*}{Apr} | P32: =IF(Calculations!A32,Settings!$B$5,"") -> & | Q32: =Calculations!K32 -> 05 | R32: =IF(Calculations!A32,Settings!$B$5,"") -> & | S32: =Calculations!L32 -> Mo\rule{0pt}{11pt} | T32: =IF(Calculations!A32,Settings!$B$5,"") -> & | U32: =Calculations!M32 -> 26 | V32: =IF(Calculations!A32,Settings!$B$5,"") -> & | W32: =Calculations!N32 -> Magnetism: Force and Field | X32: =Calculations!O32 -> \\* | Y32: =IF(Calculations!P32="","",Calculations!P32)
C33: =IF(Calculations!A33,Dates!D33,"") | D33: =IF(Calculations!A33,1,"") -> 1 | E33: =IF(Calculations!A33,Dates!I33,"") -> 4 | F33: =IF(Calculations!A33,Dates!J33,"") -> Apr | G33: =IF(Calculations!A33,Dates!K33,"") -> 7 | H33: =IF(Calculations!A33,Dates!H33,"") -> We | I33: 27 | J33: Electromagnetic Induction | K33: =IF(ISNUMBER(I33),1,0) -> 1 | M33: =Calculations!I33 | N33: =IF(Calculations!A33,Settings!$B$5,"") -> & | O33: =Calculations!J33 | P33: =IF(Calculations!A33,Settings!$B$5,"") -> & | Q33: =Calculations!K33 -> 07 | R33: =IF(Calculations!A33,Settings!$B$5,"") -> & | S33: =Calculations!L33 -> We | T33: =IF(Calculations!A33,Settings!$B$5,"") -> & | U33: =Calculations!M33 -> 27 | V33: =IF(Calculations!A33,Settings!$B$5,"") -> & | W33: =Calculations!N33 -> Electromagnetic Induction | X33: =Calculations!O33 -> \\* | Y33: =IF(Calculations!P33="","",Calculations!P33)
C34: =IF(Calculations!A34,Dates!D34,"") | D34: =IF(Calculations!A34,1,"") -> 1 | E34: =IF(Calculations!A34,Dates!I34,"") -> 4 | F34: =IF(Calculations!A34,Dates!J34,"") -> Apr | G34: =IF(Calculations!A34,Dates!K34,"") -> 9 | H34: =IF(Calculations!A34,Dates!H34,"") -> Fr | I34: \textbf{Midterm 2} | K34: =IF(ISNUMBER(I34),1,0) -> 0 | M34: =Calculations!I34 | N34: =IF(Calculations!A34,Settings!$B$5,"") -> & | O34: =Calculations!J34 | P34: =IF(Calculations!A34,Settings!$B$5,"") -> & | Q34: =Calculations!K34 -> 09 | R34: =IF(Calculations!A34,Settings!$B$5,"") -> & | S34: =Calculations!L34 -> Fr | T34: =IF(Calculations!A34,Settings!$B$5,"") -> & | U34: =Calculations!M34 -> \textbf{Midterm 2} | V34: =IF(Calculations!A34,Settings!$B$5,"") -> & | W34: =Calculations!N34 | X34: =Calculations!O34 -> \\ | Y34: =IF(Calculations!P34="","",Calculations!P34) -> \hline
C35: =IF(Calculations!A35,Dates!D35,"") -> W12 | D35: =IF(Calculations!A35,1,"") -> 1 | E35: =IF(Calculations!A35,Dates!I35,"") -> 4 | F35: =IF(Calculations!A35,Dates!J35,"") -> Apr | G35: =IF(Calculations!A35,Dates!K35,"") -> 12 | H35: =IF(Calculations!A35,Dates!H35,"") -> Mo | I35: 27 | J35: Electromagnetic Induction | K35: =IF(ISNUMBER(I35),1,0) -> 1 | M35: =Calculations!I35 -> \multirow{3}{*}{W12} | N35: =IF(Calculations!A35,Settings!$B$5,"") -> & | O35: =Calculations!J35 -> \multirow{3}{*}{Apr} | P35: =IF(Calculations!A35,Settings!$B$5,"") -> & | Q35: =Calculations!K35 -> 12 | R35: =IF(Calculations!A35,Settings!$B$5,"") -> & | S35: =Calculations!L35 -> Mo\rule{0pt}{11pt} | T35: =IF(Calculations!A35,Settings!$B$5,"") -> & | U35: =Calculations!M35 -> 27 | V35: =IF(Calculations!A35,Settings!$B$5,"") -> & | W35: =Calculations!N35 -> Electromagnetic Induction | X35: =Calculations!O35 -> \\* | Y35: =IF(Calculations!P35="","",Calculations!P35)
C36: =IF(Calculations!A36,Dates!D36,"") | D36: =IF(Calculations!A36,1,"") -> 1 | E36: =IF(Calculations!A36,Dates!I36,"") -> 4 | F36: =IF(Calculations!A36,Dates!J36,"") -> Apr | G36: =IF(Calculations!A36,Dates!K36,"") -> 14 | H36: =IF(Calculations!A36,Dates!H36,"") -> We | I36: 27 | J36: Electromagnetic Induction | K36: =IF(ISNUMBER(I36),1,0) -> 1 | M36: =Calculations!I36 | N36: =IF(Calculations!A36,Settings!$B$5,"") -> & | O36: =Calculations!J36 | P36: =IF(Calculations!A36,Settings!$B$5,"") -> & | Q36: =Calculations!K36 -> 14 | R36: =IF(Calculations!A36,Settings!$B$5,"") -> & | S36: =Calculations!L36 -> We | T36: =IF(Calculations!A36,Settings!$B$5,"") -> & | U36: =Calculations!M36 -> 27 | V36: =IF(Calculations!A36,Settings!$B$5,"") -> & | W36: =Calculations!N36 -> Electromagnetic Induction | X36: =Calculations!O36 -> \\* | Y36: =IF(Calculations!P36="","",Calculations!P36)
C37: =IF(Calculations!A37,Dates!D37,"") | D37: =IF(Calculations!A37,1,"") -> 1 | E37: =IF(Calculations!A37,Dates!I37,"") -> 4 | F37: =IF(Calculations!A37,Dates!J37,"") -> Apr | G37: =IF(Calculations!A37,Dates!K37,"") -> 16 | H37: =IF(Calculations!A37,Dates!H37,"") -> Fr | I37: 28 | J37: Alternating-Current Circuits | K37: =IF(ISNUMBER(I37),1,0) -> 1 | M37: =Calculations!I37 | N37: =IF(Calculations!A37,Settings!$B$5,"") -> & | O37: =Calculations!J37 | P37: =IF(Calculations!A37,Settings!$B$5,"") -> & | Q37: =Calculations!K37 -> 16 | R37: =IF(Calculations!A37,Settings!$B$5,"") -> & | S37: =Calculations!L37 -> Fr | T37: =IF(Calculations!A37,Settings!$B$5,"") -> & | U37: =Calculations!M37 -> 28 | V37: =IF(Calculations!A37,Settings!$B$5,"") -> & | W37: =Calculations!N37 -> Alternating-Current Circuits | X37: =Calculations!O37 -> \\ | Y37: =IF(Calculations!P37="","",Calculations!P37) -> \hline
C38: =IF(Calculations!A38,Dates!D38,"") -> W13 | D38: =IF(Calculations!A38,1,"") -> 1 | E38: =IF(Calculations!A38,Dates!I38,"") -> 4 | F38: =IF(Calculations!A38,Dates!J38,"") -> Apr | G38: =IF(Calculations!A38,Dates!K38,"") -> 19 | H38: =IF(Calculations!A38,Dates!H38,"") -> Mo | I38: No class | J38: Patriot’s Day | K38: =IF(ISNUMBER(I38),1,0) -> 0 | M38: =Calculations!I38 -> \multirow{3}{*}{W13} | N38: =IF(Calculations!A38,Settings!$B$5,"") -> & | O38: =Calculations!J38 -> \multirow{3}{*}{Apr} | P38: =IF(Calculations!A38,Settings!$B$5,"") -> & | Q38: =Calculations!K38 -> 19 | R38: =IF(Calculations!A38,Settings!$B$5,"") -> & | S38: =Calculations!L38 -> Mo\rule{0pt}{11pt} | T38: =IF(Calculations!A38,Settings!$B$5,"") -> & | U38: =Calculations!M38 -> No class | V38: =IF(Calculations!A38,Settings!$B$5,"") -> & | W38: =Calculations!N38 -> Patriot’s Day | X38: =Calculations!O38 -> \\* | Y38: =IF(Calculations!P38="","",Calculations!P38)
C39: =IF(Calculations!A39,Dates!D39,"") | D39: =IF(Calculations!A39,1,"") -> 1 | E39: =IF(Calculations!A39,Dates!I39,"") -> 4 | F39: =IF(Calculations!A39,Dates!J39,"") -> Apr | G39: =IF(Calculations!A39,Dates!K39,"") -> 21 | H39: =IF(Calculations!A39,Dates!H39,"") -> We | I39: 28 | J39: Alternating-Current Circuits | K39: =IF(ISNUMBER(I39),1,0) -> 1 | M39: =Calculations!I39 | N39: =IF(Calculations!A39,Settings!$B$5,"") -> & | O39: =Calculations!J39 | P39: =IF(Calculations!A39,Settings!$B$5,"") -> & | Q39: =Calculations!K39 -> 21 | R39: =IF(Calculations!A39,Settings!$B$5,"") -> & | S39: =Calculations!L39 -> We | T39: =IF(Calculations!A39,Settings!$B$5,"") -> & | U39: =Calculations!M39 -> 28 | V39: =IF(Calculations!A39,Settings!$B$5,"") -> & | W39: =Calculations!N39 -> Alternating-Current Circuits | X39: =Calculations!O39 -> \\* | Y39: =IF(Calculations!P39="","",Calculations!P39)
C40: =IF(Calculations!A40,Dates!D40,"") | D40: =IF(Calculations!A40,1,"") -> 1 | E40: =IF(Calculations!A40,Dates!I40,"") -> 4 | F40: =IF(Calculations!A40,Dates!J40,"") -> Apr | G40: =IF(Calculations!A40,Dates!K40,"") -> 23 | H40: =IF(Calculations!A40,Dates!H40,"") -> Fr | I40: 29 | J40: Maxwell’s Equations and Electromagnetic Waves | K40: =IF(ISNUMBER(I40),1,0) -> 1 | M40: =Calculations!I40 | N40: =IF(Calculations!A40,Settings!$B$5,"") -> & | O40: =Calculations!J40 | P40: =IF(Calculations!A40,Settings!$B$5,"") -> & | Q40: =Calculations!K40 -> 23 | R40: =IF(Calculations!A40,Settings!$B$5,"") -> & | S40: =Calculations!L40 -> Fr | T40: =IF(Calculations!A40,Settings!$B$5,"") -> & | U40: =Calculations!M40 -> 29 | V40: =IF(Calculations!A40,Settings!$B$5,"") -> & | W40: =Calculations!N40 -> Maxwell’s Equations and Electromagnetic Waves | X40: =Calculations!O40 -> \\ | Y40: =IF(Calculations!P40="","",Calculations!P40) -> \hline
...

Sheet Settings
A1: LaTeX output settings | B1: Value | D1: Workbook organization
A2: First meeting of week strut | B2: \rule{0pt}{11pt} | D2: Schedule: edit the plan in B1, B6:B10, and I:J; copy the final LaTeX table from B13.
A3: Row terminator | B3: \\ | D3: Dates: support sheet that generates possible meeting dates; no user editing is required.
A4: Week terminator | B4: \hline | D4: Calculations: support sheet that constructs the active meeting rows and LaTeX fragments; no user editing is required.
A5: Column separator | B5: & | D5: Tests: support sheet containing regression checks; no user editing is required.
A6: Invisible leading zero for one-digit chapters | B6: {\color{white}0} | D6: Export: support sheet containing one assembled LaTeX row per meeting; no user editing is required.
D7: Change fixed LaTeX fragments and the table-environment setting only in column B of this sheet.
A8: Planning summary | B8: Value | D8: Class meet days: mark any weekday in Schedule!B6:B10. Dates generates possible meeting dates within the 52-week window; Calculations keeps only rows through the final planned entry in Schedule columns I:J.
A9: Scheduled meeting rows | B9: =COUNTIF(Calculations!$A$2:$A$261,1) -> 47
A10: Numbered lecture meetings | B10: =COUNT(Schedule!I2:I261) -> 40
A11: No-class meetings | B11: =COUNTIF(Schedule!I2:I261,"No class") -> 5
A12: Exam meetings | B12: =COUNTA(Schedule!I2:I261)-COUNT(Schedule!I2:I261)-COUNTIF(Schedule!I2:I261,"No class") -> 2
A13: Last planned meeting row | B13: =MAX(IFERROR(LOOKUP(2,1/(Schedule!$I$2:$I$261<>""),ROW(Schedule!$I$2:$I$261)),1),IFERROR(LOOKUP(2,1/(Schedule!$J$2:$J$261<>""),ROW(Schedule!$J$2:$J$261)),1)) -> 48 | D13: The final active meeting is the last nonblank row in Schedule column I or J.
A14: LaTeX table environment | B14: longtable | D14: Choose "tabular" for the existing output or "longtable" to prevent page breaks inside a week.
A15: Nonbreaking row terminator | B15: \\* | D15: Used only in longtable mode on rows that are not the final row of a week.

Sheet Dates
A1: Week 1 Monday | B1: =Schedule!$B$1-WEEKDAY(Schedule!$B$1,2)+1 -> 44221 | L1: Days to next meeting
A2: Week 52 Sunday | B2: =$B$1+52*7-1 -> 44584 | C2: =IF(F2="","",IF(ROW()=2,INT((F2-$B$1)/7)+1,IF(INT((F2-$B$1)/7)<>INT((F1-$B$1)/7),INT((F2-$B$1)/7)+1,""))) -> 1 | D2: =IF(C2="","","W"&TEXT(C2,"00")) -> W01 | E2: =1 -> 1 | F2: =IF(L2="","",IF(Schedule!$B$1-1+L2<=$B$2,Schedule!$B$1-1+L2,"")) -> 44221 | G2: =IF(F2="","",TEXT(F2,"ddd")) -> Mon | H2: =IF(F2="","",CHOOSE(WEEKDAY(F2,2),"Mo","Tu","We","Th","Fr","Sa","Su")) -> Mo | I2: =IF(F2="","",MONTH(F2)) -> 1 | J2: =IF(F2="","",TEXT(F2,"mmm")) -> Jan | K2: =IF(F2="","",DAY(F2)) -> 25 | L2: =IF(COUNTA(Schedule!$B$6:$B$10)=0,"",MIN(IF(MID($B$3,WEEKDAY(Schedule!$B$1-1+1,2),1)="C",1,99),IF(MID($B$3,WEEKDAY(Schedule!$B$1-1+2,2),1)="C",2,99),IF(MID($B$3,WEEKDAY(Schedule!$B$1-1+3,2),1)="C",3,99),IF(MID($B$3,WEEKDAY(Schedule!$B$1-1+4,2),1)="C",4,99),IF(MID($B$3,WEEKDAY(Schedule!$B$1-1+5,2),1)="C",5,99),IF(MID($B$3,WEEKDAY(Schedule!$B$1-1+6,2),1)="C",6,99),IF(MID($B$3,WEEKDAY(Schedule!$B$1-1+7,2),1)="C",7,99))) -> 1
A3: Class-day mask | B3: =IF(Schedule!$B$6<>"","C","N")&IF(Schedule!$B$7<>"","C","N")&IF(Schedule!$B$8<>"","C","N")&IF(Schedule!$B$9<>"","C","N")&IF(Schedule!$B$10<>"","C","N")&"NN" -> CNCNCNN | C3: =IF(F3="","",IF(ROW()=2,INT((F3-$B$1)/7)+1,IF(INT((F3-$B$1)/7)<>INT((F2-$B$1)/7),INT((F3-$B$1)/7)+1,""))) | D3: =IF(C3="","","W"&TEXT(C3,"00")) | E3: =E2+1 -> 2 | F3: =IF(L3="","",IF(F2+L3<=$B$2,F2+L3,"")) -> 44223 | G3: =IF(F3="","",TEXT(F3,"ddd")) -> Wed | H3: =IF(F3="","",CHOOSE(WEEKDAY(F3,2),"Mo","Tu","We","Th","Fr","Sa","Su")) -> We | I3: =IF(F3="","",MONTH(F3)) -> 1 | J3: =IF(F3="","",TEXT(F3,"mmm")) -> Jan | K3: =IF(F3="","",DAY(F3)) -> 27 | L3: =IF(F2="","",MIN(IF(MID($B$3,WEEKDAY(F2+1,2),1)="C",1,99),IF(MID($B$3,WEEKDAY(F2+2,2),1)="C",2,99),IF(MID($B$3,WEEKDAY(F2+3,2),1)="C",3,99),IF(MID($B$3,WEEKDAY(F2+4,2),1)="C",4,99),IF(MID($B$3,WEEKDAY(F2+5,2),1)="C",5,99),IF(MID($B$3,WEEKDAY(F2+6,2),1)="C",6,99),IF(MID($B$3,WEEKDAY(F2+7,2),1)="C",7,99))) -> 2
C4: =IF(F4="","",IF(ROW()=2,INT((F4-$B$1)/7)+1,IF(INT((F4-$B$1)/7)<>INT((F3-$B$1)/7),INT((F4-$B$1)/7)+1,""))) | D4: =IF(C4="","","W"&TEXT(C4,"00")) | E4: =E3+1 -> 3 | F4: =IF(L4="","",IF(F3+L4<=$B$2,F3+L4,"")) -> 44225 | G4: =IF(F4="","",TEXT(F4,"ddd")) -> Fri | H4: =IF(F4="","",CHOOSE(WEEKDAY(F4,2),"Mo","Tu","We","Th","Fr","Sa","Su")) -> Fr | I4: =IF(F4="","",MONTH(F4)) -> 1 | J4: =IF(F4="","",TEXT(F4,"mmm")) -> Jan | K4: =IF(F4="","",DAY(F4)) -> 29 | L4: =IF(F3="","",MIN(IF(MID($B$3,WEEKDAY(F3+1,2),1)="C",1,99),IF(MID($B$3,WEEKDAY(F3+2,2),1)="C",2,99),IF(MID($B$3,WEEKDAY(F3+3,2),1)="C",3,99),IF(MID($B$3,WEEKDAY(F3+4,2),1)="C",4,99),IF(MID($B$3,WEEKDAY(F3+5,2),1)="C",5,99),IF(MID($B$3,WEEKDAY(F3+6,2),1)="C",6,99),IF(MID($B$3,WEEKDAY(F3+7,2),1)="C",7,99))) -> 2
C5: =IF(F5="","",IF(ROW()=2,INT((F5-$B$1)/7)+1,IF(INT((F5-$B$1)/7)<>INT((F4-$B$1)/7),INT((F5-$B$1)/7)+1,""))) -> 2 | D5: =IF(C5="","","W"&TEXT(C5,"00")) -> W02 | E5: =E4+1 -> 4 | F5: =IF(L5="","",IF(F4+L5<=$B$2,F4+L5,"")) -> 44228 | G5: =IF(F5="","",TEXT(F5,"ddd")) -> Mon | H5: =IF(F5="","",CHOOSE(WEEKDAY(F5,2),"Mo","Tu","We","Th","Fr","Sa","Su")) -> Mo | I5: =IF(F5="","",MONTH(F5)) -> 2 | J5: =IF(F5="","",TEXT(F5,"mmm")) -> Feb | K5: =IF(F5="","",DAY(F5)) -> 1 | L5: =IF(F4="","",MIN(IF(MID($B$3,WEEKDAY(F4+1,2),1)="C",1,99),IF(MID($B$3,WEEKDAY(F4+2,2),1)="C",2,99),IF(MID($B$3,WEEKDAY(F4+3,2),1)="C",3,99),IF(MID($B$3,WEEKDAY(F4+4,2),1)="C",4,99),IF(MID($B$3,WEEKDAY(F4+5,2),1)="C",5,99),IF(MID($B$3,WEEKDAY(F4+6,2),1)="C",6,99),IF(MID($B$3,WEEKDAY(F4+7,2),1)="C",7,99))) -> 3
C6: =IF(F6="","",IF(ROW()=2,INT((F6-$B$1)/7)+1,IF(INT((F6-$B$1)/7)<>INT((F5-$B$1)/7),INT((F6-$B$1)/7)+1,""))) | D6: =IF(C6="","","W"&TEXT(C6,"00")) | E6: =E5+1 -> 5 | F6: =IF(L6="","",IF(F5+L6<=$B$2,F5+L6,"")) -> 44230 | G6: =IF(F6="","",TEXT(F6,"ddd")) -> Wed | H6: =IF(F6="","",CHOOSE(WEEKDAY(F6,2),"Mo","Tu","We","Th","Fr","Sa","Su")) -> We | I6: =IF(F6="","",MONTH(F6)) -> 2 | J6: =IF(F6="","",TEXT(F6,"mmm")) -> Feb | K6: =IF(F6="","",DAY(F6)) -> 3 | L6: =IF(F5="","",MIN(IF(MID($B$3,WEEKDAY(F5+1,2),1)="C",1,99),IF(MID($B$3,WEEKDAY(F5+2,2),1)="C",2,99),IF(MID($B$3,WEEKDAY(F5+3,2),1)="C",3,99),IF(MID($B$3,WEEKDAY(F5+4,2),1)="C",4,99),IF(MID($B$3,WEEKDAY(F5+5,2),1)="C",5,99),IF(MID($B$3,WEEKDAY(F5+6,2),1)="C",6,99),IF(MID($B$3,WEEKDAY(F5+7,2),1)="C",7,99))) -> 2
C7: =IF(F7="","",IF(ROW()=2,INT((F7-$B$1)/7)+1,IF(INT((F7-$B$1)/7)<>INT((F6-$B$1)/7),INT((F7-$B$1)/7)+1,""))) | D7: =IF(C7="","","W"&TEXT(C7,"00")) | E7: =E6+1 -> 6 | F7: =IF(L7="","",IF(F6+L7<=$B$2,F6+L7,"")) -> 44232 | G7: =IF(F7="","",TEXT(F7,"ddd")) -> Fri | H7: =IF(F7="","",CHOOSE(WEEKDAY(F7,2),"Mo","Tu","We","Th","Fr","Sa","Su")) -> Fr | I7: =IF(F7="","",MONTH(F7)) -> 2 | J7: =IF(F7="","",TEXT(F7,"mmm")) -> Feb | K7: =IF(F7="","",DAY(F7)) -> 5 | L7: =IF(F6="","",MIN(IF(MID($B$3,WEEKDAY(F6+1,2),1)="C",1,99),IF(MID($B$3,WEEKDAY(F6+2,2),1)="C",2,99),IF(MID($B$3,WEEKDAY(F6+3,2),1)="C",3,99),IF(MID($B$3,WEEKDAY(F6+4,2),1)="C",4,99),IF(MID($B$3,WEEKDAY(F6+5,2),1)="C",5,99),IF(MID($B$3,WEEKDAY(F6+6,2),1)="C",6,99),IF(MID($B$3,WEEKDAY(F6+7,2),1)="C",7,99))) -> 2
C8: =IF(F8="","",IF(ROW()=2,INT((F8-$B$1)/7)+1,IF(INT((F8-$B$1)/7)<>INT((F7-$B$1)/7),INT((F8-$B$1)/7)+1,""))) -> 3 | D8: =IF(C8="","","W"&TEXT(C8,"00")) -> W03 | E8: =E7+1 -> 7 | F8: =IF(L8="","",IF(F7+L8<=$B$2,F7+L8,"")) -> 44235 | G8: =IF(F8="","",TEXT(F8,"ddd")) -> Mon | H8: =IF(F8="","",CHOOSE(WEEKDAY(F8,2),"Mo","Tu","We","Th","Fr","Sa","Su")) -> Mo | I8: =IF(F8="","",MONTH(F8)) -> 2 | J8: =IF(F8="","",TEXT(F8,"mmm")) -> Feb | K8: =IF(F8="","",DAY(F8)) -> 8 | L8: =IF(F7="","",MIN(IF(MID($B$3,WEEKDAY(F7+1,2),1)="C",1,99),IF(MID($B$3,WEEKDAY(F7+2,2),1)="C",2,99),IF(MID($B$3,WEEKDAY(F7+3,2),1)="C",3,99),IF(MID($B$3,WEEKDAY(F7+4,2),1)="C",4,99),IF(MID($B$3,WEEKDAY(F7+5,2),1)="C",5,99),IF(MID($B$3,WEEKDAY(F7+6,2),1)="C",6,99),IF(MID($B$3,WEEKDAY(F7+7,2),1)="C",7,99))) -> 3
C9: =IF(F9="","",IF(ROW()=2,INT((F9-$B$1)/7)+1,IF(INT((F9-$B$1)/7)<>INT((F8-$B$1)/7),INT((F9-$B$1)/7)+1,""))) | D9: =IF(C9="","","W"&TEXT(C9,"00")) | E9: =E8+1 -> 8 | F9: =IF(L9="","",IF(F8+L9<=$B$2,F8+L9,"")) -> 44237 | G9: =IF(F9="","",TEXT(F9,"ddd")) -> Wed | H9: =IF(F9="","",CHOOSE(WEEKDAY(F9,2),"Mo","Tu","We","Th","Fr","Sa","Su")) -> We | I9: =IF(F9="","",MONTH(F9)) -> 2 | J9: =IF(F9="","",TEXT(F9,"mmm")) -> Feb | K9: =IF(F9="","",DAY(F9)) -> 10 | L9: =IF(F8="","",MIN(IF(MID($B$3,WEEKDAY(F8+1,2),1)="C",1,99),IF(MID($B$3,WEEKDAY(F8+2,2),1)="C",2,99),IF(MID($B$3,WEEKDAY(F8+3,2),1)="C",3,99),IF(MID($B$3,WEEKDAY(F8+4,2),1)="C",4,99),IF(MID($B$3,WEEKDAY(F8+5,2),1)="C",5,99),IF(MID($B$3,WEEKDAY(F8+6,2),1)="C",6,99),IF(MID($B$3,WEEKDAY(F8+7,2),1)="C",7,99))) -> 2
C10: =IF(F10="","",IF(ROW()=2,INT((F10-$B$1)/7)+1,IF(INT((F10-$B$1)/7)<>INT((F9-$B$1)/7),INT((F10-$B$1)/7)+1,""))) | D10: =IF(C10="","","W"&TEXT(C10,"00")) | E10: =E9+1 -> 9 | F10: =IF(L10="","",IF(F9+L10<=$B$2,F9+L10,"")) -> 44239 | G10: =IF(F10="","",TEXT(F10,"ddd")) -> Fri | H10: =IF(F10="","",CHOOSE(WEEKDAY(F10,2),"Mo","Tu","We","Th","Fr","Sa","Su")) -> Fr | I10: =IF(F10="","",MONTH(F10)) -> 2 | J10: =IF(F10="","",TEXT(F10,"mmm")) -> Feb | K10: =IF(F10="","",DAY(F10)) -> 12 | L10: =IF(F9="","",MIN(IF(MID($B$3,WEEKDAY(F9+1,2),1)="C",1,99),IF(MID($B$3,WEEKDAY(F9+2,2),1)="C",2,99),IF(MID($B$3,WEEKDAY(F9+3,2),1)="C",3,99),IF(MID($B$3,WEEKDAY(F9+4,2),1)="C",4,99),IF(MID($B$3,WEEKDAY(F9+5,2),1)="C",5,99),IF(MID($B$3,WEEKDAY(F9+6,2),1)="C",6,99),IF(MID($B$3,WEEKDAY(F9+7,2),1)="C",7,99))) -> 2
C11: =IF(F11="","",IF(ROW()=2,INT((F11-$B$1)/7)+1,IF(INT((F11-$B$1)/7)<>INT((F10-$B$1)/7),INT((F11-$B$1)/7)+1,""))) -> 4 | D11: =IF(C11="","","W"&TEXT(C11,"00")) -> W04 | E11: =E10+1 -> 10 | F11: =IF(L11="","",IF(F10+L11<=$B$2,F10+L11,"")) -> 44242 | G11: =IF(F11="","",TEXT(F11,"ddd")) -> Mon | H11: =IF(F11="","",CHOOSE(WEEKDAY(F11,2),"Mo","Tu","We","Th","Fr","Sa","Su")) -> Mo | I11: =IF(F11="","",MONTH(F11)) -> 2 | J11: =IF(F11="","",TEXT(F11,"mmm")) -> Feb | K11: =IF(F11="","",DAY(F11)) -> 15 | L11: =IF(F10="","",MIN(IF(MID($B$3,WEEKDAY(F10+1,2),1)="C",1,99),IF(MID($B$3,WEEKDAY(F10+2,2),1)="C",2,99),IF(MID($B$3,WEEKDAY(F10+3,2),1)="C",3,99),IF(MID($B$3,WEEKDAY(F10+4,2),1)="C",4,99),IF(MID($B$3,WEEKDAY(F10+5,2),1)="C",5,99),IF(MID($B$3,WEEKDAY(F10+6,2),1)="C",6,99),IF(MID($B$3,WEEKDAY(F10+7,2),1)="C",7,99))) -> 3
C12: =IF(F12="","",IF(ROW()=2,INT((F12-$B$1)/7)+1,IF(INT((F12-$B$1)/7)<>INT((F11-$B$1)/7),INT((F12-$B$1)/7)+1,""))) | D12: =IF(C12="","","W"&TEXT(C12,"00")) | E12: =E11+1 -> 11 | F12: =IF(L12="","",IF(F11+L12<=$B$2,F11+L12,"")) -> 44244 | G12: =IF(F12="","",TEXT(F12,"ddd")) -> Wed | H12: =IF(F12="","",CHOOSE(WEEKDAY(F12,2),"Mo","Tu","We","Th","Fr","Sa","Su")) -> We | I12: =IF(F12="","",MONTH(F12)) -> 2 | J12: =IF(F12="","",TEXT(F12,"mmm")) -> Feb | K12: =IF(F12="","",DAY(F12)) -> 17 | L12: =IF(F11="","",MIN(IF(MID($B$3,WEEKDAY(F11+1,2),1)="C",1,99),IF(MID($B$3,WEEKDAY(F11+2,2),1)="C",2,99),IF(MID($B$3,WEEKDAY(F11+3,2),1)="C",3,99),IF(MID($B$3,WEEKDAY(F11+4,2),1)="C",4,99),IF(MID($B$3,WEEKDAY(F11+5,2),1)="C",5,99),IF(MID($B$3,WEEKDAY(F11+6,2),1)="C",6,99),IF(MID($B$3,WEEKDAY(F11+7,2),1)="C",7,99))) -> 2
C13: =IF(F13="","",IF(ROW()=2,INT((F13-$B$1)/7)+1,IF(INT((F13-$B$1)/7)<>INT((F12-$B$1)/7),INT((F13-$B$1)/7)+1,""))) | D13: =IF(C13="","","W"&TEXT(C13,"00")) | E13: =E12+1 -> 12 | F13: =IF(L13="","",IF(F12+L13<=$B$2,F12+L13,"")) -> 44246 | G13: =IF(F13="","",TEXT(F13,"ddd")) -> Fri | H13: =IF(F13="","",CHOOSE(WEEKDAY(F13,2),"Mo","Tu","We","Th","Fr","Sa","Su")) -> Fr | I13: =IF(F13="","",MONTH(F13)) -> 2 | J13: =IF(F13="","",TEXT(F13,"mmm")) -> Feb | K13: =IF(F13="","",DAY(F13)) -> 19 | L13: =IF(F12="","",MIN(IF(MID($B$3,WEEKDAY(F12+1,2),1)="C",1,99),IF(MID($B$3,WEEKDAY(F12+2,2),1)="C",2,99),IF(MID($B$3,WEEKDAY(F12+3,2),1)="C",3,99),IF(MID($B$3,WEEKDAY(F12+4,2),1)="C",4,99),IF(MID($B$3,WEEKDAY(F12+5,2),1)="C",5,99),IF(MID($B$3,WEEKDAY(F12+6,2),1)="C",6,99),IF(MID($B$3,WEEKDAY(F12+7,2),1)="C",7,99))) -> 2
C14: =IF(F14="","",IF(ROW()=2,INT((F14-$B$1)/7)+1,IF(INT((F14-$B$1)/7)<>INT((F13-$B$1)/7),INT((F14-$B$1)/7)+1,""))) -> 5 | D14: =IF(C14="","","W"&TEXT(C14,"00")) -> W05 | E14: =E13+1 -> 13 | F14: =IF(L14="","",IF(F13+L14<=$B$2,F13+L14,"")) -> 44249 | G14: =IF(F14="","",TEXT(F14,"ddd")) -> Mon | H14: =IF(F14="","",CHOOSE(WEEKDAY(F14,2),"Mo","Tu","We","Th","Fr","Sa","Su")) -> Mo | I14: =IF(F14="","",MONTH(F14)) -> 2 | J14: =IF(F14="","",TEXT(F14,"mmm")) -> Feb | K14: =IF(F14="","",DAY(F14)) -> 22 | L14: =IF(F13="","",MIN(IF(MID($B$3,WEEKDAY(F13+1,2),1)="C",1,99),IF(MID($B$3,WEEKDAY(F13+2,2),1)="C",2,99),IF(MID($B$3,WEEKDAY(F13+3,2),1)="C",3,99),IF(MID($B$3,WEEKDAY(F13+4,2),1)="C",4,99),IF(MID($B$3,WEEKDAY(F13+5,2),1)="C",5,99),IF(MID($B$3,WEEKDAY(F13+6,2),1)="C",6,99),IF(MID($B$3,WEEKDAY(F13+7,2),1)="C",7,99))) -> 3
C15: =IF(F15="","",IF(ROW()=2,INT((F15-$B$1)/7)+1,IF(INT((F15-$B$1)/7)<>INT((F14-$B$1)/7),INT((F15-$B$1)/7)+1,""))) | D15: =IF(C15="","","W"&TEXT(C15,"00")) | E15: =E14+1 -> 14 | F15: =IF(L15="","",IF(F14+L15<=$B$2,F14+L15,"")) -> 44251 | G15: =IF(F15="","",TEXT(F15,"ddd")) -> Wed | H15: =IF(F15="","",CHOOSE(WEEKDAY(F15,2),"Mo","Tu","We","Th","Fr","Sa","Su")) -> We | I15: =IF(F15="","",MONTH(F15)) -> 2 | J15: =IF(F15="","",TEXT(F15,"mmm")) -> Feb | K15: =IF(F15="","",DAY(F15)) -> 24 | L15: =IF(F14="","",MIN(IF(MID($B$3,WEEKDAY(F14+1,2),1)="C",1,99),IF(MID($B$3,WEEKDAY(F14+2,2),1)="C",2,99),IF(MID($B$3,WEEKDAY(F14+3,2),1)="C",3,99),IF(MID($B$3,WEEKDAY(F14+4,2),1)="C",4,99),IF(MID($B$3,WEEKDAY(F14+5,2),1)="C",5,99),IF(MID($B$3,WEEKDAY(F14+6,2),1)="C",6,99),IF(MID($B$3,WEEKDAY(F14+7,2),1)="C",7,99))) -> 2
... C261: =IF(F261="","",IF(ROW()=2,INT((F261-$B$1)/7)+1,IF(INT((F261-$B$1)/7)<>INT((F260-$B$1)/7),INT((F261-$B$1)/7)+1,""))) | D261: =IF(C261="","","W"&TEXT(C261,"00")) | E261: =E260+1 -> 260 | F261: =IF(L261="","",IF(F260+L261<=$B$2,F260+L261,"")) | G261: =IF(F261="","",TEXT(F261,"ddd")) | H261: =IF(F261="","",CHOOSE(WEEKDAY(F261,2),"Mo","Tu","We","Th","Fr","Sa","Su")) | I261: =IF(F261="","",MONTH(F261)) | J261: =IF(F261="","",TEXT(F261,"mmm")) | K261: =IF(F261="","",DAY(F261)) | L261: =IF(F260="","",MIN(IF(MID($B$3,WEEKDAY(F260+1,2),1)="C",1,99),IF(MID($B$3,WEEKDAY(F260+2,2),1)="C",2,99),IF(MID($B$3,WEEKDAY(F260+3,2),1)="C",3,99),IF(MID($B$3,WEEKDAY(F260+4,2),1)="C",4,99),IF(MID($B$3,WEEKDAY(F260+5,2),1)="C",5,99),IF(MID($B$3,WEEKDAY(F260+6,2),1)="C",6,99),IF(MID($B$3,WEEKDAY(F260+7,2),1)="C",7,99)))

Sheet Calculations
A1: Active row | B1: Week label | C1: First in week | D1: Last in week | E1: Rows in week | F1: Month | G1: First in month run | H1: Rows in month run | I1: Week LaTeX | J1: Month LaTeX | K1: Date LaTeX | L1: Day LaTeX | M1: Chapter LaTeX | N1: Topic LaTeX | O1: Row end | P1: Week end
A2: =AND(Dates!F2<>"",ROW()<=Settings!$B$13) -> TRUE | B2: =IF(NOT(A2),"",IF(Dates!D2<>"",Dates!D2,IF(ROW()=2,"",B1))) -> W01 | C2: =AND(A2,OR(ROW()=2,B2<>B1)) -> TRUE | D2: =AND(A2,OR(NOT(A3),B3<>B2)) -> FALSE | E2: =IF(A2,COUNTIF($B$2:$B$261,B2),0) -> 3 | F2: =IF(A2,Dates!J2,"") -> Jan | G2: =AND(A2,OR(C2,F2<>F1)) -> TRUE | H2: =IF(A2,COUNTIFS($B$2:$B$261,B2,$F$2:$F$261,F2),0) -> 3 | I2: =IF(C2,"\multirow{"&E2&"}{*}{"&B2&"}","") -> \multirow{3}{*}{W01} | J2: =IF(G2,IF(H2=1,F2,"\multirow{"&H2&"}{*}{"&F2&"}"),"") -> \multirow{3}{*}{Jan} | K2: =IF(A2,TEXT(Dates!K2,"00"),"") -> 25 | L2: =IF(A2,Dates!H2&IF(C2,Settings!$B$2,""),"") -> Mo\rule{0pt}{11pt} | M2: =IF(A2,IF(Schedule!I2="","",IF(ISNUMBER(Schedule!I2),IF(Schedule!I2<10,Settings!$B$6&TEXT(Schedule!I2,"#"),Schedule!I2),Schedule!I2)),"") -> 16 | N2: =IF(A2,IF(Schedule!J2="","",Schedule!J2),"") -> Temperature and Heat | O2: =IF(A2,IF(AND(Settings!$B$14="longtable",NOT(D2)),Settings!$B$15,Settings!$B$3),"") -> \\* | P2: =IF(D2,Settings!$B$4,"")
A3: =AND(Dates!F3<>"",ROW()<=Settings!$B$13) -> TRUE | B3: =IF(NOT(A3),"",IF(Dates!D3<>"",Dates!D3,IF(ROW()=2,"",B2))) -> W01 | C3: =AND(A3,OR(ROW()=2,B3<>B2)) -> FALSE | D3: =AND(A3,OR(NOT(A4),B4<>B3)) -> FALSE | E3: =IF(A3,COUNTIF($B$2:$B$261,B3),0) -> 3 | F3: =IF(A3,Dates!J3,"") -> Jan | G3: =AND(A3,OR(C3,F3<>F2)) -> FALSE | H3: =IF(A3,COUNTIFS($B$2:$B$261,B3,$F$2:$F$261,F3),0) -> 3 | I3: =IF(C3,"\multirow{"&E3&"}{*}{"&B3&"}","") | J3: =IF(G3,IF(H3=1,F3,"\multirow{"&H3&"}{*}{"&F3&"}"),"") | K3: =IF(A3,TEXT(Dates!K3,"00"),"") -> 27 | L3: =IF(A3,Dates!H3&IF(C3,Settings!$B$2,""),"") -> We | M3: =IF(A3,IF(Schedule!I3="","",IF(ISNUMBER(Schedule!I3),IF(Schedule!I3<10,Settings!$B$6&TEXT(Schedule!I3,"#"),Schedule!I3),Schedule!I3)),"") -> 16 | N3: =IF(A3,IF(Schedule!J3="","",Schedule!J3),"") -> Temperature and Heat | O3: =IF(A3,IF(AND(Settings!$B$14="longtable",NOT(D3)),Settings!$B$15,Settings!$B$3),"") -> \\* | P3: =IF(D3,Settings!$B$4,"")
A4: =AND(Dates!F4<>"",ROW()<=Settings!$B$13) -> TRUE | B4: =IF(NOT(A4),"",IF(Dates!D4<>"",Dates!D4,IF(ROW()=2,"",B3))) -> W01 | C4: =AND(A4,OR(ROW()=2,B4<>B3)) -> FALSE | D4: =AND(A4,OR(NOT(A5),B5<>B4)) -> TRUE | E4: =IF(A4,COUNTIF($B$2:$B$261,B4),0) -> 3 | F4: =IF(A4,Dates!J4,"") -> Jan | G4: =AND(A4,OR(C4,F4<>F3)) -> FALSE | H4: =IF(A4,COUNTIFS($B$2:$B$261,B4,$F$2:$F$261,F4),0) -> 3 | I4: =IF(C4,"\multirow{"&E4&"}{*}{"&B4&"}","") | J4: =IF(G4,IF(H4=1,F4,"\multirow{"&H4&"}{*}{"&F4&"}"),"") | K4: =IF(A4,TEXT(Dates!K4,"00"),"") -> 29 | L4: =IF(A4,Dates!H4&IF(C4,Settings!$B$2,""),"") -> Fr | M4: =IF(A4,IF(Schedule!I4="","",IF(ISNUMBER(Schedule!I4),IF(Schedule!I4<10,Settings!$B$6&TEXT(Schedule!I4,"#"),Schedule!I4),Schedule!I4)),"") -> 17 | N4: =IF(A4,IF(Schedule!J4="","",Schedule!J4),"") -> The Thermal Behavior of Matter | O4: =IF(A4,IF(AND(Settings!$B$14="longtable",NOT(D4)),Settings!$B$15,Settings!$B$3),"") -> \\ | P4: =IF(D4,Settings!$B$4,"") -> \hline
A5: =AND(Dates!F5<>"",ROW()<=Settings!$B$13) -> TRUE | B5: =IF(NOT(A5),"",IF(Dates!D5<>"",Dates!D5,IF(ROW()=2,"",B4))) -> W02 | C5: =AND(A5,OR(ROW()=2,B5<>B4)) -> TRUE | D5: =AND(A5,OR(NOT(A6),B6<>B5)) -> FALSE | E5: =IF(A5,COUNTIF($B$2:$B$261,B5),0) -> 3 | F5: =IF(A5,Dates!J5,"") -> Feb | G5: =AND(A5,OR(C5,F5<>F4)) -> TRUE | H5: =IF(A5,COUNTIFS($B$2:$B$261,B5,$F$2:$F$261,F5),0) -> 3 | I5: =IF(C5,"\multirow{"&E5&"}{*}{"&B5&"}","") -> \multirow{3}{*}{W02} | J5: =IF(G5,IF(H5=1,F5,"\multirow{"&H5&"}{*}{"&F5&"}"),"") -> \multirow{3}{*}{Feb} | K5: =IF(A5,TEXT(Dates!K5,"00"),"") -> 01 | L5: =IF(A5,Dates!H5&IF(C5,Settings!$B$2,""),"") -> Mo\rule{0pt}{11pt} | M5: =IF(A5,IF(Schedule!I5="","",IF(ISNUMBER(Schedule!I5),IF(Schedule!I5<10,Settings!$B$6&TEXT(Schedule!I5,"#"),Schedule!I5),Schedule!I5)),"") -> 17 | N5: =IF(A5,IF(Schedule!J5="","",Schedule!J5),"") -> The Thermal Behavior of Matter | O5: =IF(A5,IF(AND(Settings!$B$14="longtable",NOT(D5)),Settings!$B$15,Settings!$B$3),"") -> \\* | P5: =IF(D5,Settings!$B$4,"")
A6: =AND(Dates!F6<>"",ROW()<=Settings!$B$13) -> TRUE | B6: =IF(NOT(A6),"",IF(Dates!D6<>"",Dates!D6,IF(ROW()=2,"",B5))) -> W02 | C6: =AND(A6,OR(ROW()=2,B6<>B5)) -> FALSE | D6: =AND(A6,OR(NOT(A7),B7<>B6)) -> FALSE | E6: =IF(A6,COUNTIF($B$2:$B$261,B6),0) -> 3 | F6: =IF(A6,Dates!J6,"") -> Feb | G6: =AND(A6,OR(C6,F6<>F5)) -> FALSE | H6: =IF(A6,COUNTIFS($B$2:$B$261,B6,$F$2:$F$261,F6),0) -> 3 | I6: =IF(C6,"\multirow{"&E6&"}{*}{"&B6&"}","") | J6: =IF(G6,IF(H6=1,F6,"\multirow{"&H6&"}{*}{"&F6&"}"),"") | K6: =IF(A6,TEXT(Dates!K6,"00"),"") -> 03 | L6: =IF(A6,Dates!H6&IF(C6,Settings!$B$2,""),"") -> We | M6: =IF(A6,IF(Schedule!I6="","",IF(ISNUMBER(Schedule!I6),IF(Schedule!I6<10,Settings!$B$6&TEXT(Schedule!I6,"#"),Schedule!I6),Schedule!I6)),"") -> 18 | N6: =IF(A6,IF(Schedule!J6="","",Schedule!J6),"") -> Heat, Work, and the First Law of Thermodynamics | O6: =IF(A6,IF(AND(Settings!$B$14="longtable",NOT(D6)),Settings!$B$15,Settings!$B$3),"") -> \\* | P6: =IF(D6,Settings!$B$4,"")
A7: =AND(Dates!F7<>"",ROW()<=Settings!$B$13) -> TRUE | B7: =IF(NOT(A7),"",IF(Dates!D7<>"",Dates!D7,IF(ROW()=2,"",B6))) -> W02 | C7: =AND(A7,OR(ROW()=2,B7<>B6)) -> FALSE | D7: =AND(A7,OR(NOT(A8),B8<>B7)) -> TRUE | E7: =IF(A7,COUNTIF($B$2:$B$261,B7),0) -> 3 | F7: =IF(A7,Dates!J7,"") -> Feb | G7: =AND(A7,OR(C7,F7<>F6)) -> FALSE | H7: =IF(A7,COUNTIFS($B$2:$B$261,B7,$F$2:$F$261,F7),0) -> 3 | I7: =IF(C7,"\multirow{"&E7&"}{*}{"&B7&"}","") | J7: =IF(G7,IF(H7=1,F7,"\multirow{"&H7&"}{*}{"&F7&"}"),"") | K7: =IF(A7,TEXT(Dates!K7,"00"),"") -> 05 | L7: =IF(A7,Dates!H7&IF(C7,Settings!$B$2,""),"") -> Fr | M7: =IF(A7,IF(Schedule!I7="","",IF(ISNUMBER(Schedule!I7),IF(Schedule!I7<10,Settings!$B$6&TEXT(Schedule!I7,"#"),Schedule!I7),Schedule!I7)),"") -> 18 | N7: =IF(A7,IF(Schedule!J7="","",Schedule!J7),"") -> Heat, Work, and the First Law of Thermodynamics | O7: =IF(A7,IF(AND(Settings!$B$14="longtable",NOT(D7)),Settings!$B$15,Settings!$B$3),"") -> \\ | P7: =IF(D7,Settings!$B$4,"") -> \hline
